Traceback (most recent call last):
  File "/home/oleg/PycharmProjects/trading/venv/lib/python3.10/site-packages/sqlalchemy/engine/base.py", line 3361, in _wrap_pool_connect
    return fn()
  File "/home/oleg/PycharmProjects/trading/venv/lib/python3.10/site-packages/sqlalchemy/pool/base.py", line 310, in connect
    return _ConnectionFairy._checkout(self)
  File "/home/oleg/PycharmProjects/trading/venv/lib/python3.10/site-packages/sqlalchemy/pool/base.py", line 868, in _checkout
    fairy = _ConnectionRecord.checkout(pool)
  File "/home/oleg/PycharmProjects/trading/venv/lib/python3.10/site-packages/sqlalchemy/pool/base.py", line 476, in checkout
    rec = pool._do_get()
  File "/home/oleg/PycharmProjects/trading/venv/lib/python3.10/site-packages/sqlalchemy/pool/impl.py", line 145, in _do_get
    with util.safe_reraise():
  File "/home/oleg/PycharmProjects/trading/venv/lib/python3.10/site-packages/sqlalchemy/util/langhelpers.py", line 70, in __exit__
    compat.raise_(
  File "/home/oleg/PycharmProjects/trading/venv/lib/python3.10/site-packages/sqlalchemy/util/compat.py", line 208, in raise_
    raise exception
  File "/home/oleg/PycharmProjects/trading/venv/lib/python3.10/site-packages/sqlalchemy/pool/impl.py", line 143, in _do_get
    return self._create_connection()
  File "/home/oleg/PycharmProjects/trading/venv/lib/python3.10/site-packages/sqlalchemy/pool/base.py", line 256, in _create_connection
    return _ConnectionRecord(self)
  File "/home/oleg/PycharmProjects/trading/venv/lib/python3.10/site-packages/sqlalchemy/pool/base.py", line 371, in __init__
    self.__connect()
  File "/home/oleg/PycharmProjects/trading/venv/lib/python3.10/site-packages/sqlalchemy/pool/base.py", line 665, in __connect
    with util.safe_reraise():
  File "/home/oleg/PycharmProjects/trading/venv/lib/python3.10/site-packages/sqlalchemy/util/langhelpers.py", line 70, in __exit__
    compat.raise_(
  File "/home/oleg/PycharmProjects/trading/venv/lib/python3.10/site-packages/sqlalchemy/util/compat.py", line 208, in raise_
    raise exception
  File "/home/oleg/PycharmProjects/trading/venv/lib/python3.10/site-packages/sqlalchemy/pool/base.py", line 661, in __connect
    self.dbapi_connection = connection = pool._invoke_creator(self)
  File "/home/oleg/PycharmProjects/trading/venv/lib/python3.10/site-packages/sqlalchemy/engine/create.py", line 578, in connect
    return dialect.connect(*cargs, **cparams)
  File "/home/oleg/PycharmProjects/trading/venv/lib/python3.10/site-packages/sqlalchemy/engine/default.py", line 597, in connect
    return self.dbapi.connect(*cargs, **cparams)
  File "/home/oleg/PycharmProjects/trading/venv/lib/python3.10/site-packages/psycopg2/__init__.py", line 122, in connect
    conn = _connect(dsn, connection_factory=connection_factory, **kwasync)
psycopg2.OperationalError: connection to server at "localhost" (127.0.0.1), port 5432 failed: Connection refused
	Is the server running on that host and accepting TCP/IP connections?


The above exception was the direct cause of the following exception:

Traceback (most recent call last):
  File "/home/oleg/PycharmProjects/trading/monitor.py", line 255, in <module>
    df_monitor = update_tables(filtered=False)
  File "/home/oleg/PycharmProjects/trading/monitor.py", line 28, in update_tables
    df_monitor = pd.DataFrame(engine.execute(
  File "<string>", line 2, in execute
  File "/home/oleg/PycharmProjects/trading/venv/lib/python3.10/site-packages/sqlalchemy/util/deprecations.py", line 402, in warned
    return fn(*args, **kwargs)
  File "/home/oleg/PycharmProjects/trading/venv/lib/python3.10/site-packages/sqlalchemy/engine/base.py", line 3256, in execute
    connection = self.connect(close_with_result=True)
  File "/home/oleg/PycharmProjects/trading/venv/lib/python3.10/site-packages/sqlalchemy/engine/base.py", line 3315, in connect
    return self._connection_cls(self, close_with_result=close_with_result)
  File "/home/oleg/PycharmProjects/trading/venv/lib/python3.10/site-packages/sqlalchemy/engine/base.py", line 96, in __init__
    else engine.raw_connection()
  File "/home/oleg/PycharmProjects/trading/venv/lib/python3.10/site-packages/sqlalchemy/engine/base.py", line 3394, in raw_connection
    return self._wrap_pool_connect(self.pool.connect, _connection)
  File "/home/oleg/PycharmProjects/trading/venv/lib/python3.10/site-packages/sqlalchemy/engine/base.py", line 3364, in _wrap_pool_connect
    Connection._handle_dbapi_exception_noconnection(
  File "/home/oleg/PycharmProjects/trading/venv/lib/python3.10/site-packages/sqlalchemy/engine/base.py", line 2198, in _handle_dbapi_exception_noconnection
    util.raise_(
  File "/home/oleg/PycharmProjects/trading/venv/lib/python3.10/site-packages/sqlalchemy/util/compat.py", line 208, in raise_
    raise exception
  File "/home/oleg/PycharmProjects/trading/venv/lib/python3.10/site-packages/sqlalchemy/engine/base.py", line 3361, in _wrap_pool_connect
    return fn()
  File "/home/oleg/PycharmProjects/trading/venv/lib/python3.10/site-packages/sqlalchemy/pool/base.py", line 310, in connect
    return _ConnectionFairy._checkout(self)
  File "/home/oleg/PycharmProjects/trading/venv/lib/python3.10/site-packages/sqlalchemy/pool/base.py", line 868, in _checkout
    fairy = _ConnectionRecord.checkout(pool)
  File "/home/oleg/PycharmProjects/trading/venv/lib/python3.10/site-packages/sqlalchemy/pool/base.py", line 476, in checkout
    rec = pool._do_get()
  File "/home/oleg/PycharmProjects/trading/venv/lib/python3.10/site-packages/sqlalchemy/pool/impl.py", line 145, in _do_get
    with util.safe_reraise():
  File "/home/oleg/PycharmProjects/trading/venv/lib/python3.10/site-packages/sqlalchemy/util/langhelpers.py", line 70, in __exit__
    compat.raise_(
  File "/home/oleg/PycharmProjects/trading/venv/lib/python3.10/site-packages/sqlalchemy/util/compat.py", line 208, in raise_
    raise exception
  File "/home/oleg/PycharmProjects/trading/venv/lib/python3.10/site-packages/sqlalchemy/pool/impl.py", line 143, in _do_get
    return self._create_connection()
  File "/home/oleg/PycharmProjects/trading/venv/lib/python3.10/site-packages/sqlalchemy/pool/base.py", line 256, in _create_connection
    return _ConnectionRecord(self)
  File "/home/oleg/PycharmProjects/trading/venv/lib/python3.10/site-packages/sqlalchemy/pool/base.py", line 371, in __init__
    self.__connect()
  File "/home/oleg/PycharmProjects/trading/venv/lib/python3.10/site-packages/sqlalchemy/pool/base.py", line 665, in __connect
    with util.safe_reraise():
  File "/home/oleg/PycharmProjects/trading/venv/lib/python3.10/site-packages/sqlalchemy/util/langhelpers.py", line 70, in __exit__
    compat.raise_(
  File "/home/oleg/PycharmProjects/trading/venv/lib/python3.10/site-packages/sqlalchemy/util/compat.py", line 208, in raise_
    raise exception
  File "/home/oleg/PycharmProjects/trading/venv/lib/python3.10/site-packages/sqlalchemy/pool/base.py", line 661, in __connect
    self.dbapi_connection = connection = pool._invoke_creator(self)
  File "/home/oleg/PycharmProjects/trading/venv/lib/python3.10/site-packages/sqlalchemy/engine/create.py", line 578, in connect
    return dialect.connect(*cargs, **cparams)
  File "/home/oleg/PycharmProjects/trading/venv/lib/python3.10/site-packages/sqlalchemy/engine/default.py", line 597, in connect
    return self.dbapi.connect(*cargs, **cparams)
  File "/home/oleg/PycharmProjects/trading/venv/lib/python3.10/site-packages/psycopg2/__init__.py", line 122, in connect
    conn = _connect(dsn, connection_factory=connection_factory, **kwasync)
sqlalchemy.exc.OperationalError: (psycopg2.OperationalError) connection to server at "localhost" (127.0.0.1), port 5432 failed: Connection refused
	Is the server running on that host and accepting TCP/IP connections?

(Background on this error at: https://sqlalche.me/e/14/e3q8)
